Workbook

Sheet Constants
A1: TBL_NAME | B1: TBL_DESCR | C1: TBL_VOLUME
A2: C1_BI_FTGL_MONTHLY_A | B2: Financial Transaction GL Monthly Aggregate | C2: Medium Volume
A3: C1_BI_FT_MONTHLY_A | B3: Financial Transaction Monthly Aggregate | C3: Medium Volume
A4: C1_BI_SA_SNAPSHOT | B4: SA Arrears Snapshot | C4: Medium Volume
A5: C1_CONT | B5: Consumer Contract | C5: Medium Volume
A6: C1_CS_REQ | B6: Customer Service Request | C6: Medium Volume
A7: C1_CS_REQ_ACCT | B7: Customer Service Request Account | C7: Medium Volume
A8: C1_CS_REQ_CONT | B8: Customer Service Request Consumer Contract | C8: Medium Volume
A9: C1_CS_REQ_CONT_PROD | B9: Customer Service Request Contract Product | C9: Medium Volume
A10: C1_CS_REQ_PER | B10: Customer Service Request Person | C10: Medium Volume
A11: C1_CS_REQ_PREM | B11: Customer Service Request Premise | C11: Medium Volume
A12: C1_CS_REQ_SA | B12: Customer Service Request SA | C12: Medium Volume
... A278: W1_WORK_REQ | B278: Work Request | C278: Medium Volume

Sheet Tabulation
A1: Client | B1: Table Name | C1: Row Count | D1: Table Description | E1: Table Volume
A2: CityCorp | B2: C1_BI_FTGL_MONTHLY_A | C2: 0 | D2: =VLOOKUP(Tabulation!$B2,Constants!$A:$C,2,FALSE) -> Financial Transaction GL Monthly Aggregate | E2: =VLOOKUP(Tabulation!$B2,Constants!$A:$C,3,FALSE) -> Medium Volume
A3: CityCorp | B3: C1_BI_FT_MONTHLY_A | C3: 0 | D3: =VLOOKUP(Tabulation!$B3,Constants!$A:$C,2,FALSE) -> Financial Transaction Monthly Aggregate | E3: =VLOOKUP(Tabulation!$B3,Constants!$A:$C,3,FALSE) -> Medium Volume
A4: CityCorp | B4: C1_BI_SA_SNAPSHOT | C4: 0 | D4: =VLOOKUP(Tabulation!$B4,Constants!$A:$C,2,FALSE) -> SA Arrears Snapshot | E4: =VLOOKUP(Tabulation!$B4,Constants!$A:$C,3,FALSE) -> Medium Volume
A5: CityCorp | B5: C1_CONT | C5: 0 | D5: =VLOOKUP(Tabulation!$B5,Constants!$A:$C,2,FALSE) -> Consumer Contract | E5: =VLOOKUP(Tabulation!$B5,Constants!$A:$C,3,FALSE) -> Medium Volume
A6: CityCorp | B6: C1_CS_REQ | C6: 2031 | D6: =VLOOKUP(Tabulation!$B6,Constants!$A:$C,2,FALSE) -> Customer Service Request | E6: =VLOOKUP(Tabulation!$B6,Constants!$A:$C,3,FALSE) -> Medium Volume
A7: CityCorp | B7: C1_CS_REQ_ACCT | C7: 1569 | D7: =VLOOKUP(Tabulation!$B7,Constants!$A:$C,2,FALSE) -> Customer Service Request Account | E7: =VLOOKUP(Tabulation!$B7,Constants!$A:$C,3,FALSE) -> Medium Volume
A8: CityCorp | B8: C1_CS_REQ_CONT | C8: 0 | D8: =VLOOKUP(Tabulation!$B8,Constants!$A:$C,2,FALSE) -> Customer Service Request Consumer Contract | E8: =VLOOKUP(Tabulation!$B8,Constants!$A:$C,3,FALSE) -> Medium Volume
A9: CityCorp | B9: C1_CS_REQ_CONT_PROD | C9: 0 | D9: =VLOOKUP(Tabulation!$B9,Constants!$A:$C,2,FALSE) -> Customer Service Request Contract Product | E9: =VLOOKUP(Tabulation!$B9,Constants!$A:$C,3,FALSE) -> Medium Volume
A10: CityCorp | B10: C1_CS_REQ_PER | C10: 1558 | D10: =VLOOKUP(Tabulation!$B10,Constants!$A:$C,2,FALSE) -> Customer Service Request Person | E10: =VLOOKUP(Tabulation!$B10,Constants!$A:$C,3,FALSE) -> Medium Volume
A11: CityCorp | B11: C1_CS_REQ_PREM | C11: 1784 | D11: =VLOOKUP(Tabulation!$B11,Constants!$A:$C,2,FALSE) -> Customer Service Request Premise | E11: =VLOOKUP(Tabulation!$B11,Constants!$A:$C,3,FALSE) -> Medium Volume
A12: CityCorp | B12: C1_CS_REQ_SA | C12: 4857 | D12: =VLOOKUP(Tabulation!$B12,Constants!$A:$C,2,FALSE) -> Customer Service Request SA | E12: =VLOOKUP(Tabulation!$B12,Constants!$A:$C,3,FALSE) -> Medium Volume
A13: CityCorp | B13: C1_CS_REQ_SVC_LOC | C13: 0 | D13: =VLOOKUP(Tabulation!$B13,Constants!$A:$C,2,FALSE) -> Customer Service Request Service Location | E13: =VLOOKUP(Tabulation!$B13,Constants!$A:$C,3,FALSE) -> Medium Volume
... A1361: Newark | B1361: W1_WORK_REQ | C1361: 0 | D1361: =VLOOKUP(Tabulation!$B1361,Constants!$A:$C,2,FALSE) -> Work Request | E1361: =VLOOKUP(Tabulation!$B1361,Constants!$A:$C,3,FALSE) -> Medium Volume

Sheet Pivot
A1: Sum of Row Count | B1: Column Labels
A2: Row Labels | B2: Newark | C2: Fond du Lac | D2: Ellensburg | E2: College Station | F2: CityCorp | G2: Total | H2: Table Description | I2: Assignee | J2: Status
A3: C1_BI_FT_MONTHLY_A | B3: 0 | C3: 0 | D3: 0 | E3: 0 | F3: 0 | G3: =SUM(B3,C3,D3,E3,F3) -> 0 | H3: =VLOOKUP(A3,Constants!$A:$C,2,FALSE) -> Financial Transaction Monthly Aggregate
A4: C1_BI_FTGL_MONTHLY_A | B4: 0 | C4: 0 | D4: 0 | E4: 0 | F4: 0 | G4: =SUM(B4,C4,D4,E4,F4) -> 0 | H4: =VLOOKUP(A4,Constants!$A:$C,2,FALSE) -> Financial Transaction GL Monthly Aggregate
A5: C1_BI_SA_SNAPSHOT | B5: 0 | C5: 0 | D5: 500256 | E5: 0 | F5: 0 | G5: =SUM(B5,C5,D5,E5,F5) -> 500256 | H5: =VLOOKUP(A5,Constants!$A:$C,2,FALSE) -> SA Arrears Snapshot
A6: C1_CONT | B6: 0 | C6: 0 | D6: 0 | E6: 0 | F6: 0 | G6: =SUM(B6,C6,D6,E6,F6) -> 0 | H6: =VLOOKUP(A6,Constants!$A:$C,2,FALSE) -> Consumer Contract
A7: C1_CS_REQ | B7: 1618 | C7: 5286 | D7: 7504 | E7: 31 | F7: 2031 | G7: =SUM(B7,C7,D7,E7,F7) -> 16470 | H7: =VLOOKUP(A7,Constants!$A:$C,2,FALSE) -> Customer Service Request
A8: C1_CS_REQ_ACCT | B8: 713 | C8: 4856 | D8: 6151 | E8: 0 | F8: 1569 | G8: =SUM(B8,C8,D8,E8,F8) -> 13289 | H8: =VLOOKUP(A8,Constants!$A:$C,2,FALSE) -> Customer Service Request Account
A9: C1_CS_REQ_CONT | B9: 0 | C9: 0 | D9: 0 | E9: 0 | F9: 0 | G9: =SUM(B9,C9,D9,E9,F9) -> 0 | H9: =VLOOKUP(A9,Constants!$A:$C,2,FALSE) -> Customer Service Request Consumer Contract
A10: C1_CS_REQ_CONT_PROD | B10: 0 | C10: 0 | D10: 0 | E10: 0 | F10: 0 | G10: =SUM(B10,C10,D10,E10,F10) -> 0 | H10: =VLOOKUP(A10,Constants!$A:$C,2,FALSE) -> Customer Service Request Contract Product
A11: C1_CS_REQ_PER | B11: 722 | C11: 5079 | D11: 5557 | E11: 0 | F11: 1558 | G11: =SUM(B11,C11,D11,E11,F11) -> 12916 | H11: =VLOOKUP(A11,Constants!$A:$C,2,FALSE) -> Customer Service Request Person
A12: C1_CS_REQ_PREM | B12: 684 | C12: 4766 | D12: 5421 | E12: 0 | F12: 1784 | G12: =SUM(B12,C12,D12,E12,F12) -> 12655 | H12: =VLOOKUP(A12,Constants!$A:$C,2,FALSE) -> Customer Service Request Premise
A13: C1_CS_REQ_SA | B13: 2091 | C13: 14404 | D13: 18037 | E13: 0 | F13: 4857 | G13: =SUM(B13,C13,D13,E13,F13) -> 39389 | H13: =VLOOKUP(A13,Constants!$A:$C,2,FALSE) -> Customer Service Request SA
A14: C1_CS_REQ_SVC_LOC | B14: 0 | C14: 0 | D14: 0 | E14: 0 | F14: 0 | G14: =SUM(B14,C14,D14,E14,F14) -> 0 | H14: =VLOOKUP(A14,Constants!$A:$C,2,FALSE) -> Customer Service Request Service Location
... A24: C1_PA_RQST | B24: 358 | C24: 0 | D24: 0 | E24: 1 | F24: 0 | G24: =SUM(B24,C24,D24,E24,F24) -> 359 | H24: =VLOOKUP(A24,Constants!$A:$C,2,FALSE) -> Payment Arrangement Request
A25: C1_RESPONSE | E25: 0 | G25: =SUM(B25,C25,D25,E25,F25) -> 0 | H25: =VLOOKUP(A25,Constants!$A:$C,2,FALSE) -> Response
A26: C1_USAGE | B26: 15360951 | C26: 2173379 | D26: 445035 | E26: 1500648 | F26: 251992 | G26: =SUM(B26,C26,D26,E26,F26) -> 19732005 | H26: =VLOOKUP(A26,Constants!$A:$C,2,FALSE) -> Usage
A27: C1_WEB_USER | B27: 0 | C27: 0 | D27: 0 | E27: 0 | F27: 0 | G27: =SUM(B27,C27,D27,E27,F27) -> 0 | H27: =VLOOKUP(A27,Constants!$A:$C,2,FALSE) -> Web User
A28: C1_WEB_USER_ACCT | B28: 0 | C28: 0 | D28: 0 | E28: 0 | F28: 0 | G28: =SUM(B28,C28,D28,E28,F28) -> 0 | H28: =VLOOKUP(A28,Constants!$A:$C,2,FALSE) -> Web User Account
A29: CI_ACCT | B29: 59950 | C29: 29496 | D29: 90087 | E29: 155128 | F29: 22560 | G29: =SUM(B29,C29,D29,E29,F29) -> 357221 | H29: =VLOOKUP(A29,Constants!$A:$C,2,FALSE) -> Account
A30: CI_ADJ | B30: 8715478 | C30: 557276 | D30: 328670 | E30: 2312799 | F30: 197579 | G30: =SUM(B30,C30,D30,E30,F30) -> 12111802 | H30: =VLOOKUP(A30,Constants!$A:$C,2,FALSE) -> Adjustment
A31: CI_ADJ_STG_CTL | B31: 0 | C31: 5 | D31: 1 | E31: 0 | F31: 1 | G31: =SUM(B31,C31,D31,E31,F31) -> 7 | H31: =VLOOKUP(A31,Constants!$A:$C,2,FALSE) -> Adjustment Staging Control
A32: CI_ADJ_STG_UP | B32: 0 | C32: 22839 | D32: 1452 | E32: 0 | F32: 1468 | G32: =SUM(B32,C32,D32,E32,F32) -> 25759 | H32: =VLOOKUP(A32,Constants!$A:$C,2,FALSE) -> Adjustment Upload
A33: CI_AM_REQ | B33: 0 | C33: 0 | D33: 0 | E33: 0 | F33: 0 | G33: =SUM(B33,C33,D33,E33,F33) -> 0 | H33: =VLOOKUP(A33,Constants!$A:$C,2,FALSE) -> Activity Request
A34: CI_APPR_REQ | B34: 2468 | C34: 4252 | D34: 8818 | E34: 3127 | F34: 741 | G34: =SUM(B34,C34,D34,E34,F34) -> 19406 | H34: =VLOOKUP(A34,Constants!$A:$C,2,FALSE) -> Approval Request
A35: CI_AUDIT | B35: 0 | C35: 0 | D35: 0 | E35: 0 | F35: 1348 | G35: =SUM(B35,C35,D35,E35,F35) -> 1348 | H35: =VLOOKUP(A35,Constants!$A:$C,2,FALSE) -> Audit
A36: CI_BAL_CTL_GRP | B36: 21 | C36: 21 | D36: 15 | E36: 14 | F36: 10 | G36: =SUM(B36,C36,D36,E36,F36) -> 81 | H36: =VLOOKUP(A36,Constants!$A:$C,2,FALSE) -> Balance Control Group
A37: CI_BATCH_JOB | B37: 2928 | C37: 1319 | D37: 1329 | E37: 4256 | F37: 829 | G37: =SUM(B37,C37,D37,E37,F37) -> 10661 | H37: =VLOOKUP(A37,Constants!$A:$C,2,FALSE) -> Batch Job Ad-Hoc Queues
... A274: W1_WORK_REQ | B274: 0 | C274: 0 | D274: 0 | E274: 0 | F274: 0 | G274: =SUM(B274,C274,D274,E274,F274) -> 0 | H274: =VLOOKUP(A274,Constants!$A:$C,2,FALSE) -> Work Request
A275: CI_SPR | E275: 0 | G275: =SUM(B275,C275,D275,E275,F275) -> 0 | H275: =VLOOKUP(A275,Constants!$A:$C,2,FALSE) -> Service Provider - CCB
A276: D1_EVT_PARTICIPATION | E276: 0 | G276: =SUM(B276,C276,D276,E276,F276) -> 0 | H276: =VLOOKUP(A276,Constants!$A:$C,2,FALSE) -> Event Participation
A277: F1_BATCH_RUN_ANALYTICS_SNAP | E277: 0 | G277: =SUM(B277,C277,D277,E277,F277) -> 0 | H277: =VLOOKUP(A277,Constants!$A:$C,2,FALSE) -> Batch Run Analytics Snapshot
A278: F1_BATCH_THD_ANALYTICS_SNAP | E278: 0 | G278: =SUM(B278,C278,D278,E278,F278) -> 0 | H278: =VLOOKUP(A278,Constants!$A:$C,2,FALSE) -> Batch Thread Analytics Snapshot
A279: Grand Total | B279: 124534458 | C279: 14903796 | D279: 17545023 | E279: 76034132 | F279: 13783055 | G279: =SUM(B279,C279,D279,E279,F279) -> 246800464 | H279: =VLOOKUP(A279,Constants!$A:$C,2,FALSE) -> #N/A

Sheet Summary
A1: Table Name | B1: Table Description | C1: Newark | D1: Fond du Lac | E1: Ellensburg | F1: College Station | G1: CityCorp | H1: Total | I1: Designer | J1: Status | K1: CLOB Data Source | L1: Designer Notes | M1: Josh's Notes | N1: Link | O1: Justification
A2: C1_BI_FT_MONTHLY_A | B2: Financial Transaction Monthly Aggregate | C2: 0 | D2: 0 | E2: 0 | F2: 0 | G2: 0 | H2: 0
A3: C1_BI_FTGL_MONTHLY_A | B3: Financial Transaction GL Monthly Aggregate | C3: 0 | D3: 0 | E3: 0 | F3: 0 | G3: 0 | H3: 0
A4: C1_BI_SA_SNAPSHOT | B4: SA Arrears Snapshot | C4: 0 | D4: 0 | E4: 500256 | F4: 0 | G4: 0 | H4: 500256 | I4: Josh | J4: DEV - Complete | M4: Likely, this needs to be created as it's one of the views for OUAV
A5: C1_CONT | B5: Consumer Contract | C5: 0 | D5: 0 | E5: 0 | F5: 0 | G5: 0 | H5: 0
A6: C1_CS_REQ | B6: Customer Service Request | C6: 1618 | D6: 5286 | E6: 7504 | F6: 31 | G6: 2031 | H6: 16470 | I6: Doms | J6: Skip - Confirmed | L6: This is related to Process Flows and more on an Internal Processing of the lifecycle-based transaction. We can skip as the content is more technical than functional.
A7: C1_CS_REQ_ACCT | B7: Customer Service Request Account | C7: 713 | D7: 4856 | E7: 6151 | F7: 0 | G7: 1569 | H7: 13289 | I7: Doms | J7: Skip - Confirmed | L7: This is related to Process Flows and more on an Internal Processing of the lifecycle-based transaction. We can skip as the content is more technical than functional.
A8: C1_CS_REQ_CONT | B8: Customer Service Request Consumer Contract | C8: 0 | D8: 0 | E8: 0 | F8: 0 | G8: 0 | H8: 0
A9: C1_CS_REQ_CONT_PROD | B9: Customer Service Request Contract Product | C9: 0 | D9: 0 | E9: 0 | F9: 0 | G9: 0 | H9: 0
A10: C1_CS_REQ_PER | B10: Customer Service Request Person | C10: 722 | D10: 5079 | E10: 5557 | F10: 0 | G10: 1558 | H10: 12916 | I10: Doms | J10: Skip - Confirmed | L10: This is related to Process Flows and more on an Internal Processing of the lifecycle-based transaction. We can skip as the content is more technical than functional.
A11: C1_CS_REQ_PREM | B11: Customer Service Request Premise | C11: 684 | D11: 4766 | E11: 5421 | F11: 0 | G11: 1784 | H11: 12655 | I11: Doms | J11: Skip - Confirmed | L11: This is related to Process Flows and more on an Internal Processing of the lifecycle-based transaction. We can skip as the content is more technical than functional.
A12: C1_CS_REQ_SA | B12: Customer Service Request SA | C12: 2091 | D12: 14404 | E12: 18037 | F12: 0 | G12: 4857 | H12: 39389 | I12: Doms | J12: Skip - Confirmed | L12: This is related to Process Flows and more on an Internal Processing of the lifecycle-based transaction. We can skip as the content is more technical than functional.
A13: C1_CS_REQ_SVC_LOC | B13: Customer Service Request Service Location | C13: 0 | D13: 0 | E13: 0 | F13: 0 | G13: 0 | H13: 0
A14: C1_CUST_REL_REQ | B14: Customer Relationship Request | C14: 0 | D14: 0 | E14: 0 | F14: 0 | G14: 0 | H14: 0
A15: C1_LEAD | B15: Lead | C15: 0 | D15: 0 | E15: 0 | F15: 0 | G15: 0 | H15: 0
A16: C1_LEAD_EVT | B16: Lead Event | C16: 0 | D16: 0 | E16: 0 | F16: 0 | G16: 0 | H16: 0
A17: C1_MKT_RP | B17: Registration Point | C17: 0 | D17: 0 | E17: 0 | F17: 0 | G17: 0 | H17: 0
A18: C1_MKTMSG_CHG | B18: Market Charge | C18: 0 | D18: 0 | E18: 0 | F18: 0 | G18: 0 | H18: 0
A19: C1_MKTMSG_PAY | B19: Market Payment | C19: 0 | D19: 0 | E19: 0 | F19: 0 | G19: 0 | H19: 0
A20: C1_MKTMSG_USG | B20: Market Usage | C20: 0 | D20: 0 | E20: 0 | F20: 0 | G20: 0 | H20: 0
A21: C1_NTF_PREF | B21: Communication Preference | C21: 0 | D21: 0 | E21: 0 | F21: 0 | G21: 0 | H21: 0
A22: C1_OFFCYC_BGEN | B22: Off Cycle Bill Generator | C22: 52675 | D22: 169 | E22: 36816 | F22: 6073 | G22: 9 | H22: 95742 | I22: Doms | J22: Skip - Confirmed | L22: Agree, this is more of an internal transaction to process and correct the read and rebill of the old bill segment using the new usage. This can be skipped | M22: This is more of an internal transaction, whose results are stored in a bill. It's best to keep track of the bills instead.
A23: C1_PA_RQST | B23: Payment Arrangement Request | C23: 358 | D23: 0 | E23: 0 | F23: 1 | G23: 0 | H23: 359 | I23: Doms | J23: DEV - Complete | L23: Agree, a domain should be created as this table contains information on the arrangement downpayment, arrangement amounts, number of installments, and installment amount. | M23: This needs to be created because we don't have a fixed set of tables for the payment arrangements. We only use the SA's recurring charge history page to keep track of payment arrangements. | O23: This table contains information on the arrangement downpayment, arrangement amounts, number of installments, and installment amount.
A24: C1_RESPONSE | B24: Response | F24: 0 | H24: 0
A25: C1_USAGE | B25: C-side Usage | C25: 15360951 | D25: 2173379 | E25: 445035 | F25: 1500648 | G25: 251992 | H25: 19732005 | I25: Lennice | J25: DEV - Complete
A26: C1_WEB_USER | B26: Web User | C26: 0 | D26: 0 | E26: 0 | F26: 0 | G26: 0 | H26: 0
A27: C1_WEB_USER_ACCT | B27: Web User Account | C27: 0 | D27: 0 | E27: 0 | F27: 0 | G27: 0 | H27: 0
A28: CI_ACCT | B28: Account | C28: 59950 | D28: 29496 | E28: 90087 | F28: 155128 | G28: 22560 | H28: 357221 | I28: Josh | J28: DEV - Complete
A29: CI_ADJ | B29: Adjustment | C29: 8715478 | D29: 557276 | E29: 328670 | F29: 2312799 | G29: 197579 | H29: 12111802 | I29: Josh | J29: DEV - Complete
A30: CI_ADJ_STG_CTL | B30: Adjustment Staging Control | C30: 0 | D30: 5 | E30: 1 | F30: 0 | G30: 1 | H30: 7 | I30: Doms | J30: Skip - Confirmed | L30: Agree, this is transitory/internal transaction. This can be skipped | M30: This is a transitory transaction which results to an adjustment being created and we have a report for that already.
A31: CI_ADJ_STG_UP | B31: Adjustment Upload | C31: 0 | D31: 22839 | E31: 1452 | F31: 0 | G31: 1468 | H31: 25759 | I31: Doms | J31: Skip - Confirmed | L31: Agree, this is transitory/internal transaction. This can be skipped | M31: This is a transitory transaction which results to an adjustment being created and we have a report for that already.
A32: CI_AM_REQ | B32: Activity Request | C32: 0 | D32: 0 | E32: 0 | F32: 0 | G32: 0 | H32: 0
A33: CI_APPR_REQ | B33: Approval Request | C33: 2468 | D33: 4252 | E33: 8818 | F33: 3127 | G33: 741 | H33: 19406 | I33: Doms | J33: DEV - Complete | L33: Agree, a domain should be created as this table contains information for the Approval History of the Adjustment until it is Frozen | M33: Related to adjustments. Seems that we need to track this. | O33: This table contains information for the Approval History of the Adjustment until it is Frozen
A34: CI_AUDIT | B34: Audit | C34: 0 | D34: 0 | E34: 0 | F34: 0 | G34: 1348 | H34: 1348 | I34: Doms | J34: Skip - Confirmed | L34: We can skip this since only a few tables have audit turned on. It's also not recommended to turn on auditing for many transaction tables at this time, as it would consume a lot of database space and may cause slowness on the server. | M34: Audit of database tables. No need to keep track of this. Just use the C2M pages
A35: CI_BAL_CTL_GRP | B35: Balance Control Group | C35: 21 | D35: 21 | E35: 15 | F35: 14 | G35: 10 | H35: 81 | I35: Doms | J35: Skip - Confirmed | L35: We can skip this. The data being stored here which is the sum of Total and Current of FTs, are being processed by its background processes to check Integrity of the FTs in each historical Balance Control Group | M35: Similar to balancing deposit controls and tender controls, we should keep track of this as well. See if creating a report here is still needed as c2m looks straightforward though.
A36: CI_BATCH_JOB | B36: Batch Job Ad-Hoc Queues | C36: 2928 | D36: 1319 | E36: 1329 | F36: 4256 | G36: 829 | H36: 10661 | I36: Doms | J36: Skip - Confirmed | M36: Records on this table came from the submitted rundeck jobs. There is no need to keep track of these as we keep track of CI_BATCH_INST table separately.
A37: CI_BATCH_RUN | B37: Batch Run | C37: 312507 | D37: 446935 | E37: 394785 | F37: 443985 | G37: 305236 | H37: 1903448 | I37: Josh | J37: DEV - Complete
A38: CI_BCHG_UP | B38: Billable Charge Upload | C38: 0 | D38: 0 | E38: 0 | F38: 0 | G38: 0 | H38: 0
A39: CI_BILL | B39: Bill Header | C39: 4175472 | D39: 467909 | E39: 538151 | F39: 2582940 | G39: 740293 | H39: 8504765 | I39: Doms | J39: DEV - Complete | O39: This table contains information of the Bill Details
A40: CI_BILL_CHG | B40: Billable Charge | C40: 1893 | D40: 9626 | E40: 18110 | F40: 5394 | G40: 0 | H40: 35023 | I40: Doms | J40: Skip - Confirmed | L40: The CI_BILL_CHG table does not need to be designed since it functions as an internal/staging record. It will be picked up in the next bill, and the calculation line details will be reflected in CI_BSEG_CALC_LN. The Billable Charge ID will be linked to CI_BSEG_CALC.
...

Sheet Manual Labels
A1: Table | B1: Field | C1: Contrived Description
A2: CMS_D1_ACTIVITY_D1FA_BODA_VW | B2: APPOINTMENT_COMMENTS | C2: Appointment Comments
A3: CMS_D1_ACTIVITY_D1FA_BODA_VW | B3: APPOINTMENT_FLG | C3: Appointment Necessary
A4: CMS_D1_ACTIVITY_D1FA_BODA_VW | B4: APPOINTMENT_TAKEN_BY | C4: Appointment Taken By
A5: CMS_D1_ACTIVITY_D1FA_BODA_VW | B5: APPOINTMENT_TAKEN_DATE | C5: Appointement Taken Date
A6: CMS_D1_SP_BODA_VW | B6: SVC_QTY_IDNTFR_CD_ITEM_TYPE | C6: Item Type (SQI)

Sheet SP upgrades
A1: w1_asset

Sheet BODA
A1: Table | B1: BODA VW Created (Y/N) | C1: BODA VW Name | D1: Alternate BODA VW
A2: W1_ASSET | B2: N | C2: N/A | D2: N/A
A3: W1_NODE | B3: N | C3: N/A | D3: D1_SP
A4: D1_SP | B4: Y | C4: CMS_D1_SP_BODA_VW | D4: N/A
A5: D1_ACTIVITY | B5: Y | C5: CMS_D1_ACTIVITY_D1FA_BODA_VW | D5: N/A
A6: C1_PA_RQST | B6: Y | C6: CMS_C1_PA_RQST_BODA_VW | D6: N/A
A7: D1_ACTIVITY | B7: Y | C7: CMS_D1_ACTIVITY_D1FA_W_ML_BODA_VW | D7: N/A
A8: C1_REPRESENTATIVE | B8: Y | C8: CMS_C1_REPRESENTATIVE_BODA_VW | D8: N/A
A9: CI_APPR_REQ | B9: Y | C9: CMS_CI_APPR_REQ_BODA_VW | D9: N/A

Sheet Malformed XML DA
A1: Client | B1: Environment | C1: Table | D1: Primary Key
A2: Newark | B2: TST | C2: D1_ACTIVITY | D2: 01211419413092
A3: Newark | B3: TST | C3: D1_ACTIVITY | D3: 51125812041817

Sheet D1_ACTIVITY (with ML)
B1: Summary
B2: Table Name: D1_ACTIVITY
B3: Justification | C3: =Summary!O118 -> This table records information about Field Activities. It is useful for Clients as it allows them to easily access and extract FA-related data via reports.
B4: Designer | C4: Doms
A5: Table Name | B5: Field Name | C5: Field Description | D5: Related Table | E5: Filter | F5: Join Type | G5: Designer Notes | H5: Reviewer Notes
A6: D1_ACTIVITY | B6: D1_ACTIVITY_ID | C6: Activity ID | D6: N/A | F6: N/A
A7: D1_ACTIVITY | B7: BUS_OBJ_CD | C7: Business Object | D7: * F1_BUS_OBJ_L | F7: Inner Join
A8: D1_ACTIVITY | B8: BO_STATUS_CD | C8: Status | D8: * F1_BUS_OBJ_STATUS_L | F8: Inner Join
A9: D1_ACTIVITY | B9: ACTIVITY_TYPE_CD | C9: Activity Type | D9: * D1_ACTIVITY_TYPE * D1_ACTIVITY_TYPE_L | E9: ACTIVITY_TYPE_CAT_FLG = ‘D1FA’ | F9: Inner Join
A10: D1_ACTIVITY | B10: START_DTTM | C10: Start Date/Time | D10: N/A | F10: N/A
A11: D1_ACTIVITY | B11: END_DTTM | C11: End Date/Time | D11: N/A | F11: N/A
A12: D1_ACTIVITY | B12: CRE_DTTM | C12: Create Date/Time | D12: N/A | F12: N/A
A13: D1_ACTIVITY | B13: STATUS_UPD_DTTM | C13: Status Date/Time | D13: N/A | F13: N/A
A14: D1_ACTIVITY | B14: BO_STATUS_REASON_CD | C14: Status Reason | D14: * F1_BUS_OBJ_STATUS_RSN_L | F14: Left Join
A15: D1_ACTIVITY | B15: VERSION | C15: Version | D15: N/A | F15: N/A
A16: D1_ACTIVITY | B16: EFF_DTTM | C16: Effective Date/Time | D16: N/A | F16: N/A
A17: D1_ACTIVITY | B17: FIELD_TASK_TYPE | C17: Field Task Type | D17: * F1_EXT_LOOKUP_VAL, * F1_EXT_LOOKUP_VAL_L | E17: BUS_OBJ_CD = ‘D1-FieldTaskTypeLookup’ | F17: Inner Join
A18: D1_ACTIVITY | B18: CANCEL_REASON | C18: Cancel Reason | D18: * F1_EXT_LOOKUP_VAL * F1_EXT_LOOKUP_VAL_L | E18: BUS_OBJ_CD = ‘D1-CancelReasonLookup’ | F18: Left Join
A24: D1_ACTIVITY | B24: ILM_DT | C24: ILM Date | D24: N/A. We can ignore | F24: N/A
A25: D1_ACTIVITY | B25: ILM_ARCH_SW | C25: ILM Archive Switch | D25: N/A. We can ignore | F25: N/A
A26: D1_ACTIVITY | B26: RETENTION_PERIOD | C26: Retention Period | D26: N/A. We can ignore | F26: N/A
A27: D1_ACTIVITY | B27: RESCHEDULE_REASON | C27: Reschedule Reason | D27: * F1_EXT_LOOKUP_VAL * F1_EXT_LOOKUP_VAL_L | E27: BUS_OBJ_CD = ‘D1-RescheduleReasonLookup’ | F27: Left Outer
A28: D1_ACTIVITY | B28: EXPIRATION_DTTM | C28: Expiration Date Time | D28: BO_DATA_AREA | F28: TBD. Left Outer if we are going to use a View to get the BO_DATA_AREA values
A29: D11_ACTIVITY_REL | B29: PARENT_ACTIVITY_ID | C29: Parent Activity ID | D29: * D1_ACTIVITY_REL | E29: ACTIVITY_REL_TYPE_FLG = ‘D1PR’ | F29: Left Outer
A30: D1_SP | B30: D1_SP | C30: Service Point | D30: * D1_ACTIVITY_REL_OBJ * D1_SP | E30: MAINT_OBJ_CD = ‘D1-SP’ ACTIVITY_REL_OBJ_TYPE_FLG = ‘D1RO’ | F30: Inner Join
A31: D1_SP | B31: D1_SP_TYPE_CD | C31: Service Point Type | D31: * D1_SP * D1_SP_TYPE_L | F31: Inner Join
A32: D1_SP | B32: APPOINTMENT_WINDOW_START_DTTM | C32: Appointment Window Start Date/Time | D32: BO_DATA_AREA | F32: TBD. Left Outer if we are going to use a View to get the BO_DATA_AREA values
A33: D1_SP | B33: APPOINTMENT_WINDOW_END_DTTM | C33: Appointment Window End Date/Time | D33: BO_DATA_AREA | F33: TBD. Left Outer if we are going to use a View to get the BO_DATA_AREA values
A34: D1_SP | B34: D1_TAKEN_BY | C34: Appointment Taken By | D34: BO_DATA_AREA | F34: TBD. Left Outer if we are going to use a View to get the BO_DATA_AREA values
A35: D1_SP | B35: D1_TAKEN_DATE | C35: Appointment Taken Date | D35: BO_DATA_AREA | F35: TBD. Left Outer if we are going to use a View to get the BO_DATA_AREA values
A36: D1_SP | B36: D1_COMMENT | C36: Appointment Comment | D36: BO_DATA_AREA | F36: TBD. Left Outer if we are going to use a View to get the BO_DATA_AREA values
A37: D1_SP | B37: CR_RECIPIENT | C37: Recipient | D37: * D1_ACTIVITY_REL_OBJ * D1_SPR_L | E37: MAINT_OBJ_CD = ‘D1-SVCPROVDR’ ACTIVITY_REL_OBJ_TYPE_FLG = ‘D1RC’ | F37: Left Outer
A38: D1_SP | B38: COMMENTS | C38: Comments | D38: BO_DATA_AREA | F38: TBD. Left Outer if we are going to use a View to get the BO_DATA_AREA values
A39: D1_SP | B39: D1_INSTRUCTIONS | C39: Instructions | D39: BO_DATA_AREA | F39: TBD. Left Outer if we are going to use a View to get the BO_DATA_AREA values
A40: D1_SP | B40: D1_DEVICE_ID | C40: Device ID | D40: * D1_ACTIVITY_REL_OBJ * D1_DVC | E40: MAINT_OBJ_CD = ‘D1-DEVICE’ | F40: Left Outer
A41: D1_SP | B41: DEVICE_TYPE_CD | C41: Device Type | D41: * D1_DVC * D1_DVC_TYPE * D1_DVC_TYPE_L | F41: Left Outer
A42: D1_SP | B42: D1_BADGE_NBR | C42: Badge Number | D42: * D1_DVC * D1_DVC_IDENTIFIER | E42: DVC_ID_TYPE_FLG = ‘D1BN’ | F42: Left Outer
A43: D1_SP | B43: CR_REQUESTER | C43: Requester | D43: * D1_ACTIVITY_REL_OBJ * D1_SPR_L | E43: MAINT_OBJ_CD = ‘D1-SVCPROVDR’ ACTIVITY_REL_OBJ_TYPE_FLG = ‘D1RC’ | F43: Left Outer
A44: D1_SP | B44: CR_RQSTR_TRAN_ID | C44: Requester Transaction ID | D44: * D1_ACTIVITY_IDENTIFIER | E44: ACTIVITY_ID_TYPE_FLG = ‘D1RI’ | F44: Left Outer
A45: D1_SP | B45: EXT_REFERENCE_ID | C45: External Reference ID | D45: BO_DATA_AREA | F45: TBD.Left Join if we are going to use a View to get the BO_DATA_AREA values
...

Sheet D1_ACTIVITY (no ML)
B1: Summary
B2: Table Name: D1_ACTIVITY
B3: Justification | C3: =Summary!O118 -> This table records information about Field Activities. It is useful for Clients as it allows them to easily access and extract FA-related data via reports.
A5: Table Name | B5: Field Name | C5: Field Description | D5: Related Table | E5: Filter | F5: Join Type | G5: Designer Notes | H5: Reviewer Notes
A6: D1_ACTIVITY | B6: D1_ACTIVITY_ID | C6: Activity ID | D6: N/A | F6: N/A
A7: D1_ACTIVITY | B7: BUS_OBJ_CD | C7: Business Object | D7: * F1_BUS_OBJ_L | F7: Inner Join
A8: D1_ACTIVITY | B8: BO_STATUS_CD | C8: Status | D8: * F1_BUS_OBJ_STATUS_L | F8: Inner Join
A9: D1_ACTIVITY | B9: ACTIVITY_TYPE_CD | C9: Activity Type | D9: * D1_ACTIVITY_TYPE * D1_ACTIVITY_TYPE_L | E9: ACTIVITY_TYPE_CAT_FLG = ‘D1FA’ | F9: Inner Join
A10: D1_ACTIVITY | B10: START_DTTM | C10: Start Date/Time | D10: N/A | F10: N/A
A11: D1_ACTIVITY | B11: END_DTTM | C11: End Date/Time | D11: N/A | F11: N/A
A12: D1_ACTIVITY | B12: CRE_DTTM | C12: Create Date/Time | D12: N/A | F12: N/A
A13: D1_ACTIVITY | B13: STATUS_UPD_DTTM | C13: Status Date/Time | D13: N/A | F13: N/A
A14: D1_ACTIVITY | B14: BO_STATUS_REASON_CD | C14: Status Reason | D14: * F1_BUS_OBJ_STATUS_RSN_L | F14: Left Join
A15: D1_ACTIVITY | B15: VERSION | C15: Version | D15: N/A | F15: N/A
A16: D1_ACTIVITY | B16: EFF_DTTM | C16: Effective Date/Time | D16: N/A | F16: N/A
A17: D1_ACTIVITY | B17: FIELD_TASK_TYPE | C17: Field Task Type | D17: * F1_EXT_LOOKUP_VAL * F1_EXT_LOOKUP_VAL_L | E17: BUS_OBJ_CD = ‘D1-FieldTaskTypeLookup’ | F17: Inner Join
A18: D1_ACTIVITY | B18: CANCEL_REASON | C18: Cancel Reason | D18: * F1_EXT_LOOKUP_VAL * F1_EXT_LOOKUP_VAL_L | E18: BUS_OBJ_CD = ‘D1-CancelReasonLookup’ | F18: Left Outer
A19: D1_ACTIVITY | B19: ILM_DT | C19: ILM Date | D19: N/A. We can ignore | F19: N/A
A20: D1_ACTIVITY | B20: ILM_ARCH_SW | C20: ILM Archive Switch | D20: N/A. We can ignore | F20: N/A
A21: D1_ACTIVITY | B21: RETENTION_PERIOD | C21: Retention Period | D21: N/A. We can ignore | F21: N/A
A22: D1_ACTIVITY | B22: RESCHEDULE_REASON | C22: Reschedule Reason | D22: * F1_EXT_LOOKUP_VAL * F1_EXT_LOOKUP_VAL_L | E22: BUS_OBJ_CD = ‘D1-RescheduleReasonLookup’ | F22: Left Outer
A23: D1_ACTIVITY | B23: EXPIRATION_DTTM | C23: Expiration Date Time | D23: BO_DATA_AREA | F23: TBD. Left Outer if we are going to use a View to get the BO_DATA_AREA values
A24: D1_ACTIVITY | B24: PARENT_ACTIVITY_ID | C24: Parent Activity ID | D24: * D1_ACTIVITY_REL | E24: ACTIVITY_REL_TYPE_FLG = ‘D1PR’ | F24: Left Outer
B25: D1_SP | C25: Service Point | D25: * D1_ACTIVITY_REL_OBJ * D1_SP | E25: MAINT_OBJ_CD = ‘D1-SP’ ACTIVITY_REL_OBJ_TYPE_FLG = ‘D1RO’ | F25: Inner Join
B26: D1_SP_TYPE_CD | C26: Service Point Type | D26: * D1_SP * D1_SP_TYPE_L | F26: Inner Join
A27: CMS_D1_ACTIVITY_D1FA_BODA_VW | B27: APPOINTMENT_WINDOW_START_DTTM | C27: Appointment Window Start Date/Time | D27: BO_DATA_AREA | F27: Left Outer
B28: APPOINTMENT_WINDOW_END_DTTM | C28: Appointment Window End Date/Time | D28: BO_DATA_AREA | F28: TBD. Left Outer if we are going to use a View to get the BO_DATA_AREA values
B29: D1_TAKEN_BY | C29: Appointment Taken By | D29: BO_DATA_AREA | F29: TBD. Left Outer if we are going to use a View to get the BO_DATA_AREA values
B30: D1_TAKEN_DATE | C30: Appointment Taken Date | D30: BO_DATA_AREA | F30: TBD. Left Outer if we are going to use a View to get the BO_DATA_AREA values
B31: D1_COMMENT | C31: Appointment Comment | D31: BO_DATA_AREA | F31: TBD. Left Outer if we are going to use a View to get the BO_DATA_AREA values
B32: CR_RECIPIENT | C32: Recipient | D32: * D1_ACTIVITY_REL_OBJ * D1_SPR_L | E32: MAINT_OBJ_CD = ‘D1-SVCPROVDR’ ACTIVITY_REL_OBJ_TYPE_FLG = ‘D1RC’ | F32: Left Outer
B33: COMMENTS | C33: Comments | D33: BO_DATA_AREA | F33: TBD. Left Outer if we are going to use a View to get the BO_DATA_AREA values
B34: D1_INSTRUCTIONS | C34: Instructions | D34: BO_DATA_AREA | F34: TBD. Left Outer if we are going to use a View to get the BO_DATA_AREA values
B35: D1_DEVICE_ID | C35: Device ID | D35: * D1_ACTIVITY_REL_OBJ * D1_DVC | E35: MAINT_OBJ_CD = ‘D1-DEVICE’ | F35: Left Outer
B36: DEVICE_TYPE_CD | C36: Device Type | D36: * D1_DVC * D1_DVC_TYPE * D1_DVC_TYPE_L | F36: Left Outer
B37: D1_BADGE_NBR | C37: Badge Number | D37: * D1_DVC * D1_DVC_IDENTIFIER | E37: DVC_ID_TYPE_FLG = ‘D1BN’ | F37: Left Outer
B38: CR_REQUESTER | C38: Requester | D38: * D1_ACTIVITY_REL_OBJ * D1_SPR_L | E38: MAINT_OBJ_CD = ‘D1-SVCPROVDR’ ACTIVITY_REL_OBJ_TYPE_FLG = ‘D1RC’ | F38: Left Outer
B39: CR_REQUESTER | C39: Requester Transaction ID | D39: * D1_ACTIVITY_IDENTIFIER | E39: ACTIVITY_ID_TYPE_FLG = ‘D1RI’ | F39: Left Outer
B40: EXT_REFERENCE_ID | C40: External Reference ID | D40: BO_DATA_AREA | F40: TBD. Left Outer if we are going to use a View to get the BO_DATA_AREA values
B41: ADDRESS1_UPR | C41: Address | D41: D1_SP | F41: Inner Join
...

Sheet D1_ACTIVITY
B1: Summary
B2: Table Name: D1_ACTIVITY
B3: Data Area: D1-FieldActivity
B4: Justification | C4: =Summary!O118 -> This table records information about Field Activities. It is useful for Clients as it allows them to easily access and extract FA-related data via reports.
A6: Table Name | B6: Field Name | C6: Field Description | D6: Related Table / XPAth | E6: Filter | F6: Join Type | G6: Designer Notes | H6: Reviewer Notes
A7: D1_ACTIVITY | B7: ACTIVITY_TYPE_CD | C7: Activity Type | D7: D1_ACTIVITY_TYPE_L | E7: ACTIVITY_TYPE_CAT_FLG = 'D1FA' | F7: Left Join
A8: D1_ACTIVITY | B8: BO_DATA_AREA | C8: Business Object Data Area | D8: N/A | F8: N/A
A9: D1_ACTIVITY | B9: BO_STATUS_CD | C9: Status | D9: F1_BUS_OBJ_STATUS_L | F9: Inner Join
A10: D1_ACTIVITY | B10: BO_STATUS_REASON_CD | C10: Status Reason | D10: F1_BUS_OBJ_STATUS_RSN_L | F10: Left Join
A11: D1_ACTIVITY | B11: BUS_OBJ_CD | C11: Business Object | D11: F1_BUS_OBJ_L | F11: Inner Join
A12: D1_ACTIVITY | B12: CANCEL_REASON | C12: Cancel Reason | D12: F1_EXT_LOOKUP_VAL_L | E12: BUS_OBJ_CD = 'D1-CancelReasonLookup' | F12: Left Outer
A13: D1_ACTIVITY | B13: CRE_DTTM | C13: Create Date/Time | D13: N/A | F13: N/A
A14: D1_ACTIVITY | B14: D1_ACTIVITY_ID | C14: Activity ID | D14: N/A | F14: N/A
A15: D1_ACTIVITY | B15: EFF_DTTM | C15: Effective Date/Time | D15: N/A | F15: N/A
A16: D1_ACTIVITY | B16: END_DTTM | C16: End Date/Time | D16: N/A | F16: N/A
A17: D1_ACTIVITY | B17: FIELD_TASK_TYPE | C17: Field Task Type | D17: F1_EXT_LOOKUP_VAL_L | E17: BUS_OBJ_CD = 'D1-FieldTaskTypeLookup' | F17: Left Outer
A18: D1_ACTIVITY | B18: ILM_ARCH_SW | C18: ILM Archive Switch | D18: N/A | F18: N/A
A19: D1_ACTIVITY | B19: ILM_DT | C19: ILM Date | D19: N/A | F19: N/A
A20: D1_ACTIVITY | B20: RESCHEDULE_REASON | C20: Reschedule Reason | D20: F1_EXT_LOOKUP_VAL_L | E20: BUS_OBJ_CD = 'D1-RescheduleReasonLookup' | F20: Left Outer
A21: D1_ACTIVITY | B21: RETENTION_PERIOD | C21: Retention Period | D21: N/A | F21: N/A
A22: D1_ACTIVITY | B22: START_DTTM | C22: Start Date/Time | D22: N/A | F22: N/A
A23: D1_ACTIVITY | B23: STATUS_UPD_DTTM | C23: Status Date/Time | D23: N/A | F23: N/A
A24: D1_ACTIVITY | B24: VERSION | C24: Version | D24: N/A | F24: N/A
A25: D1_ACTIVITY_REL (linkage) | B25: ACTIVITY_REL_TYPE_FLG | C25: Activity Relationship Type | E25: FIELD_NAME = 'ACTIVITY_REL_TYPE_FLG' Field_VALUE = parent | F25: Left Outer
A26: D1_ACTIVITY_REL (linkage) | B26: D1_ACTIVITY_ID | C26: Activity ID | D26: N/A | F26: N/A
A27: D1_ACTIVITY_REL (linkage) | B27: REL_ACTIVITY_ID | C27: Related Activity | D27: D1_ACTIVITY | F27: Right Outer
A28: D1_ACTIVITY_REL (linkage) | B28: VERSION | C28: Version | D28: N/A | F28: N/A
A29: D1_ACTIVITY_REL_OBJ (linkage to D1_SP) | B29: ACTIVITY_REL_OBJ_TYPE_FLG | C29: Activity Related Object Type | D29: N/A | E29: ACTIVITY_REL_OBJ_TYPE_FLG = 'D1RO' | F29: Right Outer
A30: D1_ACTIVITY_REL_OBJ (linkage to D1_SP) | B30: D1_ACTIVITY_ID | C30: Activity ID | D30: D1_ACTIVITY | F30: Right Outer
A31: D1_ACTIVITY_REL_OBJ (linkage to D1_SP) | B31: MAINT_OBJ_CD | C31: Maintenance Object | D31: CI_MD_MO_L | E31: MAINT_OBJ_CD = 'D1-SP' | F31: Inner Join
A32: D1_ACTIVITY_REL_OBJ (linkage to D1_SP) | B32: PK_VALUE1 | C32: Primary Key 1 | D32: N/A | F32: N/A
A33: D1_ACTIVITY_REL_OBJ (linkage to D1_SP) | B33: PK_VALUE2 | C33: Primary Key 2 | D33: N/A | F33: N/A
A34: D1_ACTIVITY_REL_OBJ (linkage to D1_SP) | B34: PK_VALUE3 | C34: Primary Key 3 | D34: N/A | F34: N/A
A35: D1_ACTIVITY_REL_OBJ (linkage to D1_SP) | B35: PK_VALUE4 | C35: Primary Key 4 | D35: N/A | F35: N/A
A36: D1_ACTIVITY_REL_OBJ (linkage to D1_SP) | B36: PK_VALUE5 | C36: Primary Key 5 | D36: N/A | F36: N/A
A37: D1_ACTIVITY_REL_OBJ (linkage to D1_SP) | B37: VERSION | C37: Version | D37: N/A | F37: N/A
A38: CMS_D1_ACTIVITY_D1FA_BODA_VW | B38: APPOINTMENT_COMMENTS | C38: Appointment Comments | D38: N/A | F38: N/A
A39: CMS_D1_ACTIVITY_D1FA_BODA_VW | B39: APPOINTMENT_FLG | C39: Appointment | D39: N/A | F39: N/A
A40: CMS_D1_ACTIVITY_D1FA_BODA_VW | B40: APPOINTMENT_TAKEN_BY | C40: Appointment Taken By | D40: N/A | F40: N/A
A41: CMS_D1_ACTIVITY_D1FA_BODA_VW | B41: APPOINTMENT_TAKEN_DATE | C41: Appointment Taken Date | D41: N/A | F41: N/A
...

Sheet D1_DVC
B1: Summary
B2: Table Name: D1_DVC
B3: Justification: | C3: =Summary!O127 -> This table records information about a Device. It is useful for Clients as it allows them to view information of existing Device in C2M. Where they're located or if they're installed at a Service Point. | L3: Domain -> Device
B4: Designer: | C4: =Summary!I127 -> Lennice | L4: D1_DVC - display | N4: done
L5: D1_DVC_CFG - display | N5: done
A6: Table Name | B6: Field Name | C6: Field Description | D6: Related Table/ Xpath | E6: Filter | F6: Join Type | G6: Designer Notes | H6: Reviewer Notes | L6: D1_INSTALL_EVT - display | N6: done
A7: D1_DVC | B7: D1_DEVICE_ID | C7: Device ID | D7: N/A | F7: N/A | L7: D1_SP - link only | N7: done
A8: D1_DVC | B8: DEVICE_TYPE_CD | C8: Device Type | D8: * D1_DVC_TYPE * D1_DVC_TYPE_L | F8: Inner Join | L8: CI_PREM - display | N8: done
A9: D1_DVC | B9: BUS_OBJ_CD | C9: Business Object | D9: * F1_BUS_OBJ_L | F9: Inner Join | L9: CI_ACCT - link
A10: D1_DVC | B10: MANUFACTURER_CD | C10: Manufacturer | D10: * D1_MANUFACTURER_L | F10: Left Outer | L10: CI_PER_NAME - display
A11: D1_DVC | B11: D1_MODEL_CD | C11: Model | D11: * D1_MODEL_L | F11: Left Outer | L11: D1_SP_CONTACT | N11: n/a
A12: D1_DVC | B12: D1_SPR_CD | C12: Service Provider | D12: D1_SPR_L | F12: Left Outer
A13: D1_DVC | B13: IN_DATA_SHIFT_FLG | C13: Incoming Data Shift | D13: * CI_LOOKUP_VAL_L | F13: Left Outer
A14: D1_DVC | B14: BO_STATUS_CD | C14: Status | D14: * F1_BUS_OBJ_STATUS_L | F14: Inner Join
A15: D1_DVC | B15: STATUS_UPD_DTTM | C15: Status Date/Time | D15: N/A | F15: N/A | L15: Change to MEASUREMENT
A16: D1_DVC | B16: BO_STATUS_REASON_CD | C16: Status Reason | D16: * F1_BUS_OBJ_STATUS_RSN_L | F16: Left Outer | L16: D1_DVC
A17: D1_DVC | B17: CRE_DTTM | C17: Create Date/Time | D17: N/A | F17: N/A | L17: D1_DVC_CFG
A18: D1_DVC | B18: BO_DATA_AREA | C18: Business Object Data Area | D18: N/A | F18: N/A | L18: D1_DVC_CFG_CHAR --remove
A19: D1_DVC | B19: VERSION | C19: Version | D19: N/A | F19: N/A | L19: D1_INSTALL_EVT - link only
A20: D1_DVC | B20: ARMING_REQ_FLG | C20: Arming Required | D20: * CI_LOOKUP_VAL_L | E20: Field = ARMING_REQ_FLG | F20: Left Outer | L20: D1_MEASR_COMP - display
A21: D1_DVC | B21: HEAD_END_REGISTR_STATUS_FLG | C21: Head-End Registration Status | D21: * CI_LOOKUP_VAL_L | E21: Field = HEAD_END_REGISTR_STATUS_FLG | F21: Left Outer | L21: D1_MSRMT - display
A22: D1_DVC | B22: D1_CMD_SET_CD | C22: Command Set | D22: * D1_COMMAND_SET_L | F22: Left Outer
A23: D1_DVC | B23: ACCESS_GRP_CD | C23: Access Group | D23: * CI_ACC_GRP_L | F23: Left Outer | L23: Device Events
B24: BO_STATUS_CD | C24: Status | D24: * F1_BUS_OBJ_STATUS_L * latestBoStatus | F24: Left Outer | G24: This information is stored on BO_DATA_AREA. Not all records have this value | L24: D1_DVC_EVT -display
B25: RETIREMENT_DTTM | C25: Retirement Date/Time | D25: * retirementDateTime | F25: Left Outer | G25: This information is stored on BO_DATA_AREA. Not all records have this value | L25: D1_DVC - display
A26: D1_DVC_IDENTIFIER | B26: DVC_ID_TYPE_FLG | C26: Device Identifier Type | D26: * CI_LOOKUP_VAL_L | E26: Field = DVC_ID_TYPE_FLG | F26: Inner Join
A27: D1_DVC_IDENTIFIER | B27: ID_VALUE | C27: Identifier Value | D27: * D1_DVC_IDENTIFIER | E27: DVC_ID_TYPE_FLG = D1BN | F27: Inner Join | L27: MDM Usage - not needed included in CI_BSEG_SQ Domain
A28: D1_DVC_CFG | B28: DEVICE_CONFIG_ID | C28: Device Configuration | D28: * D1_DVC | E28: D1_DEVICE_ID | F28: Inner Join | G28: Retrieve using Device Id | L28: D1_USAGE
A29: D1_DVC_CFG | B29: DEVICE_CONFIG_TYPE_CD | C29: Device Configuration Type | D29: * D1_DVC_CFG_TYPE_L | F29: Inner Join | L29: C1_USAGE
A30: D1_DVC_CFG | B30: EFF_DTTM | C30: Effective Date/Time | F30: Inner Join | L30: CI_BSEG
A31: D1_DVC_CFG | B31: BO_STATUS_CD | C31: Status | D31: * F1_BUS_OBJ | F31: Inner Join | L31: D1_USAGE_PERIOD_SQ
A32: D1_INSTALL_EVT | B32: INSTALL_EVT_ID | C32: Install Event ID | D32: * D1_DVC_CFG | E32: DEVICE_CONFIG_ID | F32: Left Outer | G32: Retrieve using Device Config Id | L32: D1_USAGE_EXCP
A33: D1_INSTALL_EVT | B33: BO_STATUS_CD | C33: Status Date/Time | D33: * F1_BUS_OBJ_STATUS_L | E33: BUS_OBJ_CD in D1-ItemInstallEvent,D1-ManualMeterInstallEvent,D1-SmartMeterInstallEvent | F33: Left Outer | G33: Retrieve using Device Config Id
A34: D1_INSTALL_EVT | B34: D1_INSTALL_DTTM | C34: Install Date/Time | G34: Retrieve the latest install date
A35: D1_INSTALL_EVT | B35: D1_REMOVAL_DTTM | C35: Removal Date/Time | G35: Retrieve the latest removal date | L35: D1_SP - TBD check if can be included on the Customer Information
L36: D1_US
L37: D1_SP_CONTACT - add to device
A38: FROM JACOB | L38: D1_SP_IDENTIFIER
A39: D1_INSTALL_EVT | B39: ARM_STAT_FLG | C39: Arming Status | D39: N/A | F39: N/A | L39: D1_INSTALL_EVT - to display
A40: D1_INSTALL_EVT | B40: BO_DATA_AREA | C40: Business Object Data Area | D40: N/A | F40: N/A
...

Sheet Measurement
A4: Table Name | B4: Field Name | C4: Field Description | D4: Related Table/ Xpath | E4: Filter | F4: Join Type | G4: Designer Notes | H4: Reviewer Notes
A5: D1_DVC | B5: D1_DEVICE_ID | C5: Device ID | D5: N/A | F5: N/A
A6: D1_DVC | B6: DEVICE_TYPE_CD | C6: Device Type | D6: * D1_DVC_TYPE * D1_DVC_TYPE_L | F6: Inner Join
A7: D1_DVC | B7: BUS_OBJ_CD | C7: Business Object | D7: * F1_BUS_OBJ_L | F7: Inner Join
A8: D1_DVC | B8: MANUFACTURER_CD | C8: Manufacturer | D8: * D1_MANUFACTURER_L | F8: Left Outer
A9: D1_DVC | B9: D1_MODEL_CD | C9: Model | D9: * D1_MODEL_L | F9: Left Outer
A10: D1_DVC | B10: D1_SPR_CD | C10: Service Provider | D10: D1_SPR_L | F10: Left Outer
A11: D1_DVC | B11: IN_DATA_SHIFT_FLG | C11: Incoming Data Shift | D11: * CI_LOOKUP_VAL_L | F11: Left Outer
A12: D1_DVC | B12: BO_STATUS_CD | C12: Status | D12: * F1_BUS_OBJ_STATUS_L | F12: Inner Join
A13: D1_DVC | B13: STATUS_UPD_DTTM | C13: Status Date/Time | D13: N/A | F13: N/A
A14: D1_DVC | B14: BO_STATUS_REASON_CD | C14: Status Reason | D14: * F1_BUS_OBJ_STATUS_RSN_L | F14: Left Outer
A15: D1_DVC | B15: CRE_DTTM | C15: Create Date/Time | D15: N/A | F15: N/A
A16: D1_DVC | B16: BO_DATA_AREA | C16: Business Object Data Area | D16: N/A | F16: N/A
A17: D1_DVC | B17: VERSION | C17: Version | D17: N/A | F17: N/A
A18: D1_DVC | B18: ARMING_REQ_FLG | C18: Arming Required | D18: * CI_LOOKUP_VAL_L | E18: Field = ARMING_REQ_FLG | F18: Left Outer
A19: D1_DVC | B19: HEAD_END_REGISTR_STATUS_FLG | C19: Head-End Registration Status | D19: * CI_LOOKUP_VAL_L | E19: Field = HEAD_END_REGISTR_STATUS_FLG | F19: Left Outer
A20: D1_DVC | B20: D1_CMD_SET_CD | C20: Command Set | D20: * D1_COMMAND_SET_L | F20: Left Outer
A21: D1_DVC | B21: ACCESS_GRP_CD | C21: Access Group | D21: * CI_ACC_GRP_L | F21: Left Outer
B22: BO_STATUS_CD | C22: Status | D22: * F1_BUS_OBJ_STATUS_L * latestBoStatus | F22: Left Outer | G22: This information is stored on BO_DATA_AREA. Not all records have this value
B23: RETIREMENT_DTTM | C23: Retirement Date/Time | D23: * retirementDateTime | F23: Left Outer | G23: This information is stored on BO_DATA_AREA. Not all records have this value
A24: D1_DVC_CFG | B24: DEVICE_CONFIG_ID | C24: Device Configuration | D24: N/A | F24: N/A
A25: D1_DVC_CFG | B25: DEVICE_CONFIG_TYPE_CD | C25: Device Configuration Type | D25: * D1_DVC_CFG_TYPE * D1_DVC_CFG_TYPE_L | F25: Inner Join
A26: D1_DVC_CFG | B26: BUS_OBJ_CD | C26: Business Object | D26: F1_BUS_OBJ_L | F26: Inner Join
A27: D1_DVC_CFG | B27: D1_DEVICE_ID | C27: Device ID | D27: * D1_DVC | F27: Inner Join
A28: D1_DVC_CFG | B28: EFF_DTTM | C28: Effective Date/Time | D28: N/A | F28: N/A
A29: D1_DVC_CFG | B29: TIME_ZONE_CD | C29: Time Zone | D29: * CI_TIME_ZONE_L | F29: Inner Join
A30: D1_DVC_CFG | B30: BO_STATUS_CD | C30: Status | D30: * F1_BUS_OBJ_STATUS_L | F30: Inner Join | H30: Adhoc Filter
A31: D1_DVC_CFG | B31: STATUS_UPD_DTTM | C31: Status Date/Time | D31: N/A | F31: N/A
A32: D1_DVC_CFG | B32: BO_STATUS_REASON_CD | C32: Status Reason | D32: * F1_BUS_OBJ_STATUS_RSN_L | F32: Left Outer
A33: D1_DVC_CFG | B33: CRE_DTTM | C33: Create Date/Time | D33: N/A | F33: N/A
A34: D1_DVC_CFG | B34: BO_DATA_AREA | C34: Business Object Data Area | D34: N/A | F34: N/A | G34: No element is stored on this field.
A35: D1_DVC_CFG | B35: VERSION | C35: Version | D35: N/A | F35: N/A
A36: D1_INSTALL_EVT | B36: INSTALL_EVT_ID | C36: Install Event ID | D36: N/A | F36: N/A
A37: D1_INSTALL_EVT | B37: DEVICE_CONFIG_ID | C37: Device Configuration | D37: * D1_DVC_CFG | E37: INSTALL_EVT_ID | F37: Inner
A38: D1_INSTALL_EVT | B38: INSTALLATION_CONST | C38: Installation Constant | D38: N/A | F38: N/A
A39: D1_INSTALL_EVT | B39: BUS_OBJ_CD | C39: Business Object | D39: * F1_BUS_OBJ_L | F39: Inner Join
A40: D1_INSTALL_EVT | B40: BO_STATUS_CD | C40: Status | D40: * F1_BUS_OBJ_STATUS_L | E40: BO_STATUS_CD IN ('ON','CONN-COMM') | F40: Inner Join | G40: This would retrieve all the devices that were installed/removed to an SP | H40: Adhoc Filter
A41: D1_INSTALL_EVT | B41: BO_STATUS_REASON_CD | C41: Status Reason | D41: * F1_BUS_OBJ_STATUS_RSN_L | F41: Left Join
A42: D1_INSTALL_EVT | B42: STATUS_UPD_DTTM | C42: Status Date/Time | D42: N/A | F42: N/A
A43: D1_INSTALL_EVT | B43: CRE_DTTM | C43: Create Date/Time | D43: N/A | F43: N/A
...

Sheet D1_DVC_CFG
B1: Summary
B2: Table Name: D1_MSRMT
B3: Justification: | C3: =Summary!O128 -> Device configurations represent specific configurations of a device as of a certain time. During the life of a device it can have different configuration (effective-dated). A device configuration can have one or more measuring component associated with it. It is useful for Clients as it allows them to easily access and extract the information. These includes Install Event and Measuring Component and Device.
B4: Designer | C4: =Summary!I128 -> Lennice
A6: Table Name | B6: Field Name | C6: Field Description | D6: Related Table/ Xpath | E6: Filter | F6: Join Type | G6: Designer Notes | H6: Reviewer Notes
A7: D1_DVC_CFG | B7: DEVICE_CONFIG_ID | C7: Device Configuration | D7: N/A | F7: N/A
A8: D1_DVC_CFG | B8: DEVICE_CONFIG_TYPE_CD | C8: Device Configuration Type | D8: * D1_DVC_CFG_TYPE * D1_DVC_CFG_TYPE_L | F8: Inner Join
A9: D1_DVC_CFG | B9: BUS_OBJ_CD | C9: Business Object | D9: F1_BUS_OBJ_L | F9: Inner Join
A10: D1_DVC_CFG | B10: D1_DEVICE_ID | C10: Device ID | D10: * D1_DVC | F10: Inner Join
A11: D1_DVC_CFG | B11: EFF_DTTM | C11: Effective Date/Time | D11: N/A | F11: N/A
A12: D1_DVC_CFG | B12: TIME_ZONE_CD | C12: Time Zone | D12: * CI_TIME_ZONE_L | F12: Inner Join
A13: D1_DVC_CFG | B13: BO_STATUS_CD | C13: Status | D13: * F1_BUS_OBJ_STATUS_L | F13: Inner Join
A14: D1_DVC_CFG | B14: STATUS_UPD_DTTM | C14: Status Date/Time | D14: N/A | F14: N/A
A15: D1_DVC_CFG | B15: BO_STATUS_REASON_CD | C15: Status Reason | D15: * F1_BUS_OBJ_STATUS_RSN_L | F15: Left Outer
A16: D1_DVC_CFG | B16: CRE_DTTM | C16: Create Date/Time | D16: N/A | F16: N/A
A17: D1_DVC_CFG | B17: BO_DATA_AREA | C17: Business Object Data Area | D17: N/A | F17: N/A | G17: No element is stored on this field.
A18: D1_DVC_CFG | B18: VERSION | C18: Version | D18: N/A | F18: N/A
A19: D1_DVC_CFG_CHAR | B19: D1_DEVICE_ID | C19: Device ID | D19: * D1_DVC
A20: D1_DVC_CFG_CHAR | B20: D1_DC_EXTERNAL_ID | C20: External Id | D20: * D1_DVC_CFG_CHAR | E20: CHAR_TYPE_CD = ‘D1-EXTID’ | F20: Left Outer | G20: Found data in City Corp and Ellensburg
A21: D1_DVC_CFG_CHAR | B21: D1_MDM_DC_EXTERNAL_ID | C21: MDM External Id | D21: * D1_DVC_CFG_CHAR | E21: CHAR_TYPE_CD = ‘D1-EXMID’ | F21: Left Outer
A22: D1_INSTALL_EVT | B22: INSTALL_EVT_ID | C22: Install Event Id | D22: * D1_INSTALL_EVT | E22: DEVICE_CONFIG_ID | F22: Left Outer
A23: D1_INSTALL_EVT | B23: D1_SP_ID | C23: Service Point Id | D23: * D1_INSTALL_EVT | F23: Inner Join
A24: D1_INSTALL_EVT | B24: BO_STATUS_CD | C24: Status | D24: * D1_INSTALL_EVT | E24: BO_STATUS_CD IN ('ON','CONN-COMM') | F24: Inner Join | G24: This filter is only for the installed device on the SP at the given date. Other filters will be included in the D1_INSTALL_EVT domain
A25: D1_MEASR_COMP | B25: MEASR_COMP_ID | C25: Measuring Component ID | D25: * D1_MEASR_COMP | E25: DEVICE_CONFIG_ID | F25: Inner Join | G25: This is dependent if the Install Event is Connected/Commissioned or ON
A26: D1_MEASR_COMP | B26: MEASR_COMP_TYPE_CD | C26: Measuring Component Type | D26: * D1_MEASR_COMP_TYPE_L | F26: Inner Join
A27: D1_MEASR_COMP | B27: LATEST_MSRMT_DTTM | C27: Latest Measurement Date/Time | D27: * D1_MEASR_COMP | F27: Left Outer | G27: This would only provide the most recent non estimated read date but not the actual measurement value.
A28: D1_MEASR_COMP | B28: MOST_RECENT_NON_EST_MSRMT_DTTM | C28: Most Recent Non Estimated Read Date/Time | D28: * D1_MEASR_COMP | F28: Left Outer | G28: This would only provide the most recent non estimated read date but not the actual measurement value.
A29: D1_MSRMT | B29: MEASR_COMP_ID | C29: Measuring Component ID | D29: * D1_MEASR_COMP | E29: MEASR_COMP_ID | F29: Left Outer
A30: D1_MSRMT | B30: MSRMT_DTTM | C30: Measurement Date/Time | D30: * D1_MSRMT | E30: MSRMT_LOCAL_DTTM >='LATEST_MSRMT_DTTM' | F30: Left Outer | G30: This needs to be specific as only the latest/most recent value is retrieved
A31: D1_MSRMT | B31: MSRMT_VAL | C31: Measurement | D31: * D1_MSRMT | F31: Left Outer
A32: D1_MSRMT | B32: MSRMT_COND_FLG | C32: Condition | D32: * F1_EXT_LOOKUP_VAL * F1_EXT_LOOKUP_VAL_L | E32: BUS_OBJ_CD='D1-MeasurementConditionLookup' | F32: Left Outer
A35: SELECT A1.DEVICE_CONFIG_ID, A1.DEVICE_CONFIG_TYPE_CD, A1.D1_DEVICE_ID, A1.EFF_DTTM, A2.INSTALL_EVT_ID, A2.D1_SP_ID, A2.BO_STATUS_CD, A3.MEASR_COMP_ID, A3.MEASR_COMP_TYPE_CD, A3.LATEST_MSRMT_DTTM, A3.MOST_RECENT_NON_EST_MSRMT_DTTM, A4.MSRMT_COND_FLG, A4.MSRMT_DTTM, A4.MSRMT_VAL, A4.ORIG_INIT_MSRMT_ID FROM CISADM.D1_DVC_CFG A1 JOIN CISADM.D1_INSTALL_EVT A2 ON A1.DEVICE_CONFIG_ID = A2.DEVICE_CONFIG_ID JOIN CISADM.D1_MEASR_COMP A3 ON A2.DEVICE_CONFIG_ID = A3.DEVICE_CONFIG_ID JOIN CISADM.D1_MSRMT A4 ON A3.MEASR_COMP_ID = A4.MEASR_COMP_ID WHERE A2.BO_STATUS_CD IN ('ON', 'CONN-COMM') AND A1.DEVICE_CONFIG_ID = '895680366000' AND A4.MSRMT_LOCAL_DTTM >= TO_DATE('27-APR-25', 'DD-MON-YY');

Sheet D1_DVC_EVT
B1: Summary
B2: Table Name: D1_DVC_EVT
B3: Justification | C3: =Summary!O129 -> Device events are developments that have taken place relative to a device, and can include power outages, power restorations, tampering alerts, command completions, among others.
A5: Table Name | B5: Field Name | C5: Field Description | D5: Related Table/ Xpath | E5: Filter | F5: Join Type | G5: Designer Notes | H5: Designer Notes
A6: D1_DVC_EVT | B6: DVC_EVT_ID | C6: Device Event ID | D6: N/A | F6: N/A
A7: D1_DVC_EVT | B7: DVC_EVT_TYPE_CD | C7: Device Event Type | D7: * D1_DVC_EVT_TYPE * D1_DVC_EVT_TYPE_L | F7: Inner Join
A8: D1_DVC_EVT | B8: BUS_OBJ_CD | C8: Business Object | D8: * F1_BUS_OBJ_STATUS_L | F8: Inner Join
A9: D1_DVC_EVT | B9: EXT_EVT_NAME_FLG | C9: External Event Name | D9: * CI_LOOKUP_VAL_L | E9: Field: EXT_EVT_NAME_FLG | F9: Left Outer
A10: D1_DVC_EVT | B10: D1_SPR_CD | C10: Service Provider | D10: * D1_SPR_L | F10: Inner Join
A11: D1_DVC_EVT | B11: BO_STATUS_CD | C11: Status | D11: * F1_BUS_OBJ_STATUS_L | F11: Inner Join
A12: D1_DVC_EVT | B12: STATUS_UPD_DTTM | C12: Status Date/Time | D12: N/A | F12: N/A
A13: D1_DVC_EVT | B13: BO_STATUS_REASON_CD | C13: Status Reason | D13: * F1_BUS_OBJ_STATUS_RSN_L | F13: Left Outer
A14: D1_DVC_EVT | B14: DVC_EVT_END_DTTM | C14: Device Event End Date/Time | D14: N/A | F14: N/A
A15: D1_DVC_EVT | B15: CRE_DTTM | C15: Create Date/Time | D15: N/A | F15: N/A
A16: D1_DVC_EVT | B16: VERSION | C16: Version | D16: N/A | F16: N/A
A17: D1_DVC_EVT | B17: DVC_EVT_DTTM | C17: Device Event Date/Time | D17: N/A | F17: N/A
A18: D1_DVC_EVT | B18: D1_DEVICE_ID | C18: Device ID | D18: * D1_DVC | F18: Inner Join
A19: D1_DVC_EVT | B19: ILM_DT | C19: ILM Date | D19: N/A | F19: N/A
A20: D1_DVC_EVT | B20: ILM_ARCH_SW | C20: ILM Archive Switch | D20: N/A | F20: N/A
A21: D1_DVC_EVT | B21: RETENTION_PERIOD | C21: Retention Period | D21: N/A | F21: N/A
B22: SENDER_LBL | C22: Sender | D22: * BO_DATA_AREA | G22: Inner Join if we are going to use a View to get the BO_DATA_AREA values

Sheet D1_INSTALL_EVT
A1: Summary
A2: Table Name: | B2: D1_INSTALL_EVT
A3: Justification | B3: =Summary!O135 -> The Install Event records the history of the device that has been installed or removed at a Service Point. It is useful for Clients as it allows them to easily fetch the list of Service Points and the related device history
A4: Designer | B4: =Summary!I135 -> Lennice
A6: Table Name | B6: Field Name | C6: Field Description | D6: Related Table / XPAth | E6: Filter | F6: Join Type | G6: Designer Notes | H6: Reviewer Notes | J6: SELECT A1.INSTALL_EVT_ID, A1.D1_SP_ID, A1.DEVICE_CONFIG_ID, A1.BO_STATUS_CD, A3.DEVICE_CONFIG_TYPE_CD, A2.BO_STATUS_CD, A4.MEASR_COMP_ID, A4.MEASR_COMP_TYPE_CD, A4.MOST_RECENT_MSRMT_DTTM, A4.MOST_RECENT_NON_EST_MSRMT_DTTM FROM CISADM.D1_INSTALL_EVT A1 JOIN CISADM.D1_SP A2 ON A2.D1_SP_ID = A1.D1_SP_ID JOIN CISADM.D1_DVC_CFG A3 ON A1.DEVICE_CONFIG_ID = A3.DEVICE_CONFIG_ID JOIN CISADM.D1_MEASR_COMP A4 ON A3.DEVICE_CONFIG_ID = A4.DEVICE_CONFIG_ID WHERE A1.BO_STATUS_CD IN ('ON', 'CONN-COMM', 'OFF', 'REMOVE', 'DISCONN-COMM', 'CONN-DECOMM');
A7: D1_INSTALL_EVT | B7: INSTALL_EVT_ID | C7: Install Event ID | D7: N/A | F7: N/A
A8: D1_INSTALL_EVT | B8: DEVICE_CONFIG_ID | C8: Device Configuration | D8: * D1_DVC_CFG | E8: INSTALL_EVT_ID | F8: Inner
A9: D1_INSTALL_EVT | B9: INSTALLATION_CONST | C9: Installation Constant | D9: N/A | F9: N/A
A10: D1_INSTALL_EVT | B10: BUS_OBJ_CD | C10: Business Object | D10: * F1_BUS_OBJ_L | F10: Inner Join
A11: D1_INSTALL_EVT | B11: BO_STATUS_CD | C11: Status | D11: * F1_BUS_OBJ_STATUS_L | E11: BO_STATUS_CD IN ('ON','CONN-COMM','OFF','REMOVE','DISCONN-COMM','CONN-DECOMM') | F11: Inner Join | G11: This would retrieve all the devices that were installed/removed to an SP | J11: D1_DVC_IDENTIFIER | K11: ID_VALUE | L11: Identifier Value | M11: * D1_DVC_IDENTIFIER | N11: D1_DEVICE_ID DVC_ID_TYPE_FLG = D1BN | O11: Inner Join | P11: Can be removed and only use the install event status to filter the meter related to the SP
A12: D1_INSTALL_EVT | B12: BO_STATUS_REASON_CD | C12: Status Reason | D12: * F1_BUS_OBJ_STATUS_RSN_L | F12: Left Join | J12: D1_DVC_CFG | K12: DEVICE_CONFIG_ID | L12: Device Configuration | M12: * D1_INSTALL_EVT | N12: INSTALL_EVT_ID | O12: Inner
A13: D1_INSTALL_EVT | B13: STATUS_UPD_DTTM | C13: Status Date/Time | D13: N/A | F13: N/A | J13: D1_DVC_CFG | K13: D1_DEVICE_ID | L13: Device ID | M13: * D1_DVC_CFG | N13: DEVICE_CONFIG_ID | O13: Inner Join | P13: Retrieve device using the device config from the install event table
A14: D1_INSTALL_EVT | B14: CRE_DTTM | C14: Create Date/Time | D14: N/A | F14: N/A | J14: D1_DVC | K14: D1_DEVICE_ID | L14: Device ID | M14: * D1_DVC_CFG | N14: D1_DEVICE_ID
A15: D1_INSTALL_EVT | B15: BO_DATA_AREA | C15: Business Object Data Area | D15: N/A | F15: N/A | G15: Retrieve the Removal Type, Crew from the CLOB that could be used as reference | J15: D1_DVC | K15: DEVICE_TYPE_CD | L15: Device Type | P15: Added as part of the comment in SC WS by Analytics - Working Doc
A16: VIEW | B16: EVT_DTTM | C16: Date/Time | D16: eventDateTime | J16: D1_SP | K16: D1_SP_TYPE_CD | L16: Service Point Type | M16: * D1_SP_TYPE_CD_L | N16: D1_SP_ID | O16: Inner Join
A17: VIEW | B17: BO_STATUS_CD | C17: Status | D17: latestBoStatus | J17: D1_MEASR_COMP | K17: MEASR_COMP_ID | L17: Measuring Component ID | M17: * D1_MEASR_COMP | N17: DEVICE_CONFIG_ID | O17: Inner Join | P17: This is dependent if the Install Event is Connected/Commissioned or ON
A18: VIEW | B18: REMOVAL_TYPE_FLG | C18: Removal Type | D18: * CI_LOOKUP_VAL_L | E18: Field = REMOVAL_TYPE_FLG | J18: D1_MEASR_COMP | K18: MEASR_COMP_TYPE_CD | L18: Measuring Component Type | M18: * D1_MEASR_COMP_TYPE_L | O18: Inner Join
A19: VIEW | B19: CREW | J19: D1_MEASR_COMP | K19: LATEST_MSRMT_DTTM | L19: Latest Measurement Date/Time | M19: * D1_MEASR_COMP | O19: Left Outer | P19: This would only provide the most recent non estimated read date but not the actual measurement value.
A20: D1_INSTALL_EVT | B20: VERSION | C20: Version | D20: N/A | F20: N/A | J20: D1_MEASR_COMP | K20: MOST_RECENT_NON_EST_MSRMT_DTTM | L20: Most Recent Non Estimated Read Date/Time | M20: * D1_MEASR_COMP | O20: Left Outer | P20: This would only provide the most recent non estimated read date but not the actual measurement value.
A21: D1_INSTALL_EVT | B21: D1_SP_ID | C21: Service Point ID | D21: * D1_SP | E21: INSTALL_EVT_ID | F21: Inner Join
A22: D1_INSTALL_EVT | B22: ARM_STAT_FLG | C22: Arming Status | D22: N/A | F22: N/A
A23: D1_INSTALL_EVT | B23: D1_INSTALL_DTTM | C23: Installation Date/Time | D23: N/A | F23: N/A
A24: D1_INSTALL_EVT | B24: D1_REMOVAL_DTTM | C24: Removal Date/Time | D24: N/A | F24: N/A
A25: D1_DVC_IDENTIFIER | B25: ID_VALUE | C25: Identifier Value | D25: * D1_DVC_IDENTIFIER | E25: D1_DEVICE_ID DVC_ID_TYPE_FLG = D1BN | F25: Inner Join | G25: Can be removed and only use the install event status to filter the meter related to the SP
A26: D1_DVC_CFG | B26: DEVICE_CONFIG_ID | C26: Device Configuration | D26: * D1_INSTALL_EVT | E26: INSTALL_EVT_ID | F26: Inner
A27: D1_DVC_CFG | B27: D1_DEVICE_ID | C27: Device ID | D27: * D1_DVC_CFG | E27: DEVICE_CONFIG_ID | F27: Inner Join | G27: Retrieve device using the device config from the install event table
A28: D1_DVC | B28: D1_DEVICE_ID | C28: Device ID | D28: * D1_DVC_CFG | E28: D1_DEVICE_ID
A29: D1_DVC | B29: DEVICE_TYPE_CD | C29: Device Type | G29: Added as part of the comment in SC WS by Analytics - Working Doc
A30: D1_SP | B30: D1_SP_TYPE_CD | C30: Service Point Type | D30: * D1_SP_TYPE_CD_L | E30: D1_SP_ID | F30: Inner Join
A31: D1_MEASR_COMP | B31: MEASR_COMP_ID | C31: Measuring Component ID | D31: * D1_MEASR_COMP | E31: DEVICE_CONFIG_ID | F31: Inner Join | G31: This is dependent if the Install Event is Connected/Commissioned or ON
A32: D1_MEASR_COMP | B32: MEASR_COMP_TYPE_CD | C32: Measuring Component Type | D32: * D1_MEASR_COMP_TYPE_L | F32: Inner Join
A33: D1_MEASR_COMP | B33: LATEST_MSRMT_DTTM | C33: Latest Measurement Date/Time | D33: * D1_MEASR_COMP | F33: Left Outer | G33: This would only provide the most recent non estimated read date but not the actual measurement value.
A34: D1_MEASR_COMP | B34: MOST_RECENT_NON_EST_MSRMT_DTTM | C34: Most Recent Non Estimated Read Date/Time | D34: * D1_MEASR_COMP | F34: Left Outer | G34: This would only provide the most recent non estimated read date but not the actual measurement value.

Sheet D1_INIT_MSRMT_DATA
B1: Summary
B2: Table Name: | C2: D1_INIT_MSRMT_DATA
B3: Justification | C3: =Summary!O133 -> Initial measurement data (IMD) is the term for measurement data in its initial (or raw) form. This is received from an external system or user created or system estimated in C2M. Once it's processed it will be stored as measurement(D1_MSRMT) or the IMD will be in Exception state depending on the VEE Rules setup. It is useful for Clients as it allows them to review the information of the expected number of reads uploaded to the system and how many are processed at a given period of time. Note: This table holds a lot of data as a meter can have daily IMDs loaded into C2M. The adhoc view would be used to limit it via Badge Number, Measuring Component and IMD Date.
B4: Designer | C4: =Summary!I133 -> Lennice
A6: Table | B6: Field Name | C6: Field Description | D6: Related Table | E6: Filter | F6: Join Type | G6: Designer Notes | H6: Reviewer Notes
A7: D1_INIT_MSRMT_DATA | B7: BO_STATUS_CD | C7: Status | D7: * F1_BUS_OBJ_STATUS_L | F7: Inner Join
A8: D1_INIT_MSRMT_DATA | B8: BO_STATUS_REASON_CD | C8: Status Reason | D8: * F1_BUS_OBJ_STATUS_RSN_L | F8: Left Join
A9: D1_INIT_MSRMT_DATA | B9: BUS_OBJ_CD | C9: Business Object | D9: * F1_BUS_OBJ_L | F9: Inner Join
A10: D1_INIT_MSRMT_DATA | B10: CRE_DTTM | C10: Create Date/Time
A11: D1_INIT_MSRMT_DATA | B11: D1_FROM_DTTM | C11: From Date/Time
A12: D1_INIT_MSRMT_DATA | B12: D1_TO_DTTM | C12: To Date/Time
A13: D1_INIT_MSRMT_DATA | B13: DATA_SRC_FLG | C13: Data Source | D13: * CI_LOOKUP_VAL_L | E13: Field: DATA_SRC_FLG
A14: D1_INIT_MSRMT_DATA | B14: ILM_ARCH_SW | C14: ILM Archive Switch
A15: D1_INIT_MSRMT_DATA | B15: ILM_DT | C15: ILM Date
A16: D1_INIT_MSRMT_DATA | B16: IMD_BO_DATA_AREA | C16: IMD Data Area
A17: D1_INIT_MSRMT_DATA | B17: IMD_EXT_ID | C17: External ID
A18: D1_INIT_MSRMT_DATA | B18: INIT_MSRMT_DATA_ID | C18: Initial Measurement Data ID
A19: D1_INIT_MSRMT_DATA | B19: LAST_UPDATE_DTTM | C19: Last Update Timestamp
A20: D1_INIT_MSRMT_DATA | B20: MEASR_COMP_ID | C20: Measuring Component ID | D20: * D1_MEASR_COMP | F20: Left Outer
A21: D1_INIT_MSRMT_DATA | B21: POSTVEE_BO_DATA_AREA | C21: Post VEE BO Data Area
A22: D1_INIT_MSRMT_DATA | B22: PREVEE_BO_DATA_AREA | C22: Pre VEE BO Data Area
A23: D1_INIT_MSRMT_DATA | B23: RAW_BO_DATA_AREA | C23: Raw BO Data Area
A24: D1_INIT_MSRMT_DATA | B24: RETENTION_PERIOD | C24: Retention Period
A25: D1_INIT_MSRMT_DATA | B25: STATUS_UPD_DTTM | C25: Status Date/Time
A26: D1_INIT_MSRMT_DATA | B26: TIME_ZONE_CD | C26: Time Zone | D26: * CI_TIME_ZONE_L
A27: D1_INIT_MSRMT_DATA | B27: TRACE_BO_DATA_AREA | C27: Trace BO Data Area
A28: D1_INIT_MSRMT_DATA | B28: VERSION | C28: Version
A29: D1_MEASR_COMP | B29: ACCESS_GRP_CD | C29: Access Group
A30: D1_MEASR_COMP | B30: ADJ_LATEST_MSRMT_DTTM | C30: Adjust Latest Measurement Date/Time
A31: D1_MEASR_COMP | B31: ATTR_VAL_ID | C31: Attribute Value ID
A32: D1_MEASR_COMP | B32: BO_DATA_AREA | C32: Business Object Data Area
A33: D1_MEASR_COMP | B33: BO_STATUS_CD | C33: Status
A34: D1_MEASR_COMP | B34: BO_STATUS_REASON_CD | C34: Status Reason
A35: D1_MEASR_COMP | B35: BUS_OBJ_CD | C35: Business Object
A36: D1_MEASR_COMP | B36: CRE_DTTM | C36: Create Date/Time
A37: D1_MEASR_COMP | B37: D1_FULL_SCALE | C37: Full Scale
A38: D1_MEASR_COMP | B38: D1_NBR_OF_DGTS_LFT | C38: Number of Digits Left
